INFO 2025-03-31 01:59:22,979 autoreload 61992 8545306688 /Users/aemo/Projects/api_sataiga/api_sataiga/api/use_cases/prototype_use_case.py changed, reloading.
INFO 2025-03-31 01:59:24,213 autoreload 73663 8545306688 Watching for file changes with StatReloader
INFO 2025-03-31 02:16:54,419 autoreload 73663 8545306688 /Users/aemo/Projects/api_sataiga/api_sataiga/api/views/__init__.py changed, reloading.
INFO 2025-03-31 02:16:54,789 autoreload 86285 8545306688 Watching for file changes with StatReloader
INFO 2025-03-31 02:18:06,895 autoreload 86285 8545306688 /Users/aemo/Projects/api_sataiga/api_sataiga/api/use_cases/volumetry_use_case.py changed, reloading.
INFO 2025-03-31 02:18:07,235 autoreload 87172 8545306688 Watching for file changes with StatReloader
INFO 2025-03-31 02:18:32,073 autoreload 87172 8545306688 /Users/aemo/Projects/api_sataiga/api_sataiga/api/urls.py changed, reloading.
INFO 2025-03-31 02:18:32,384 autoreload 87480 8545306688 Watching for file changes with StatReloader
INFO 2025-03-31 02:34:34,915 autoreload 87480 8545306688 /Users/aemo/Projects/api_sataiga/api_sataiga/api/use_cases/volumetry_use_case.py changed, reloading.
INFO 2025-03-31 02:34:35,351 autoreload 99161 8545306688 Watching for file changes with StatReloader
INFO 2025-03-31 02:42:14,916 autoreload 99161 8545306688 /Users/aemo/Projects/api_sataiga/api_sataiga/api/use_cases/prototype_use_case.py changed, reloading.
INFO 2025-03-31 02:42:15,424 autoreload 4953 8545306688 Watching for file changes with StatReloader
INFO 2025-03-31 02:42:34,185 autoreload 4953 8545306688 /Users/aemo/Projects/api_sataiga/api_sataiga/api/use_cases/prototype_use_case.py changed, reloading.
INFO 2025-03-31 02:42:34,614 autoreload 5219 8545306688 Watching for file changes with StatReloader
INFO 2025-03-31 02:45:12,719 autoreload 5219 8545306688 /Users/aemo/Projects/api_sataiga/api_sataiga/api/use_cases/prototype_use_case.py changed, reloading.
INFO 2025-03-31 02:45:13,122 autoreload 7233 8545306688 Watching for file changes with StatReloader
INFO 2025-03-31 02:45:39,057 autoreload 7233 8545306688 /Users/aemo/Projects/api_sataiga/api_sataiga/api/use_cases/prototype_use_case.py changed, reloading.
INFO 2025-03-31 02:45:39,334 autoreload 7572 8545306688 Watching for file changes with StatReloader
INFO 2025-03-31 02:46:00,102 autoreload 7572 8545306688 /Users/aemo/Projects/api_sataiga/api_sataiga/api/use_cases/prototype_use_case.py changed, reloading.
INFO 2025-03-31 02:46:00,439 autoreload 7827 8545306688 Watching for file changes with StatReloader
INFO 2025-03-31 02:49:40,717 autoreload 7827 8545306688 /Users/aemo/Projects/api_sataiga/api_sataiga/api/views/prototype.py changed, reloading.
INFO 2025-03-31 02:49:41,035 autoreload 10459 8545306688 Watching for file changes with StatReloader
INFO 2025-03-31 02:51:53,541 autoreload 10459 8545306688 /Users/aemo/Projects/api_sataiga/api_sataiga/api/views/prototype.py changed, reloading.
INFO 2025-03-31 02:51:53,905 autoreload 12044 8545306688 Watching for file changes with StatReloader
INFO 2025-03-31 02:52:07,494 autoreload 12044 8545306688 /Users/aemo/Projects/api_sataiga/api_sataiga/api/views/__init__.py changed, reloading.
INFO 2025-03-31 02:52:07,812 autoreload 12241 8545306688 Watching for file changes with StatReloader
INFO 2025-03-31 02:55:01,682 autoreload 12241 8545306688 /Users/aemo/Projects/api_sataiga/api_sataiga/api/urls.py changed, reloading.
INFO 2025-03-31 02:55:02,037 autoreload 14355 8545306688 Watching for file changes with StatReloader
INFO 2025-03-31 03:05:10,555 autoreload 14355 8545306688 /Users/aemo/Projects/api_sataiga/api_sataiga/api/use_cases/prototype_use_case.py changed, reloading.
INFO 2025-03-31 03:05:10,971 autoreload 21751 8545306688 Watching for file changes with StatReloader
INFO 2025-03-31 03:05:17,328 autoreload 21751 8545306688 /Users/aemo/Projects/api_sataiga/api_sataiga/api/use_cases/prototype_use_case.py changed, reloading.
INFO 2025-03-31 03:05:17,621 autoreload 21838 8545306688 Watching for file changes with StatReloader
INFO 2025-03-31 03:06:41,197 autoreload 21838 8545306688 /Users/aemo/Projects/api_sataiga/api_sataiga/api/use_cases/prototype_use_case.py changed, reloading.
INFO 2025-03-31 03:06:41,596 autoreload 22871 8545306688 Watching for file changes with StatReloader
WARNING 2025-03-31 03:08:58,439 log 22871 6185660416 Bad Request: /api/prototype_by_client/67e733da54de9d1fe1378fb8
ERROR 2025-03-31 03:10:18,883 exception 22871 6185660416 Ocurri贸 una excepci贸n: 'dict' object has no attribute 'name'
ERROR 2025-03-31 03:10:18,889 exception 22871 6185660416 Detalles del traceback:
Traceback (most recent call last):
  File "/Users/aemo/Projects/api_sataiga/venv/lib/python3.13/site-packages/django/core/handlers/base.py", line 197, in _get_response
    response = wrapped_callback(request, *callback_args, **callback_kwargs)
  File "/Users/aemo/Projects/api_sataiga/venv/lib/python3.13/site-packages/django/views/decorators/csrf.py", line 65, in _view_wrapper
    return view_func(request, *args, **kwargs)
  File "/Users/aemo/Projects/api_sataiga/venv/lib/python3.13/site-packages/django/views/generic/base.py", line 104, in view
    return self.dispatch(request, *args, **kwargs)
           ~~~~~~~~~~~~~^^^^^^^^^^^^^^^^^^^^^^^^^^
  File "/Users/aemo/Projects/api_sataiga/venv/lib/python3.13/site-packages/rest_framework/views.py", line 509, in dispatch
    response = self.handle_exception(exc)
  File "/Users/aemo/Projects/api_sataiga/venv/lib/python3.13/site-packages/rest_framework/views.py", line 469, in handle_exception
    self.raise_uncaught_exception(exc)
    ~~~~~~~~~~~~~~~~~~~~~~~~~~~~~^^^^^
  File "/Users/aemo/Projects/api_sataiga/venv/lib/python3.13/site-packages/rest_framework/views.py", line 480, in raise_uncaught_exception
    raise exc
  File "/Users/aemo/Projects/api_sataiga/venv/lib/python3.13/site-packages/rest_framework/views.py", line 506, in dispatch
    response = handler(request, *args, **kwargs)
  File "/Users/aemo/Projects/api_sataiga/api_sataiga/api/views/prototype.py", line 35, in get
    return use_case.get_by_client()
           ~~~~~~~~~~~~~~~~~~~~~~^^
  File "/Users/aemo/Projects/api_sataiga/api_sataiga/api/use_cases/prototype_use_case.py", line 77, in get_by_client
    return not_found(f'No se encontraron protoripos para el cliente: {client.name}')
                                                                      ^^^^^^^^^^^
AttributeError: 'dict' object has no attribute 'name'

ERROR 2025-03-31 03:10:18,889 log 22871 6185660416 Internal Server Error: /api/prototype_by_client/67ea0785f84d6a0c075d0c2a
ERROR 2025-03-31 03:10:26,321 exception 22871 6185660416 Ocurri贸 una excepci贸n: 'dict' object has no attribute 'name'
ERROR 2025-03-31 03:10:26,323 exception 22871 6185660416 Detalles del traceback:
Traceback (most recent call last):
  File "/Users/aemo/Projects/api_sataiga/venv/lib/python3.13/site-packages/django/core/handlers/base.py", line 197, in _get_response
    response = wrapped_callback(request, *callback_args, **callback_kwargs)
  File "/Users/aemo/Projects/api_sataiga/venv/lib/python3.13/site-packages/django/views/decorators/csrf.py", line 65, in _view_wrapper
    return view_func(request, *args, **kwargs)
  File "/Users/aemo/Projects/api_sataiga/venv/lib/python3.13/site-packages/django/views/generic/base.py", line 104, in view
    return self.dispatch(request, *args, **kwargs)
           ~~~~~~~~~~~~~^^^^^^^^^^^^^^^^^^^^^^^^^^
  File "/Users/aemo/Projects/api_sataiga/venv/lib/python3.13/site-packages/rest_framework/views.py", line 509, in dispatch
    response = self.handle_exception(exc)
  File "/Users/aemo/Projects/api_sataiga/venv/lib/python3.13/site-packages/rest_framework/views.py", line 469, in handle_exception
    self.raise_uncaught_exception(exc)
    ~~~~~~~~~~~~~~~~~~~~~~~~~~~~~^^^^^
  File "/Users/aemo/Projects/api_sataiga/venv/lib/python3.13/site-packages/rest_framework/views.py", line 480, in raise_uncaught_exception
    raise exc
  File "/Users/aemo/Projects/api_sataiga/venv/lib/python3.13/site-packages/rest_framework/views.py", line 506, in dispatch
    response = handler(request, *args, **kwargs)
  File "/Users/aemo/Projects/api_sataiga/api_sataiga/api/views/prototype.py", line 35, in get
    return use_case.get_by_client()
           ~~~~~~~~~~~~~~~~~~~~~~^^
  File "/Users/aemo/Projects/api_sataiga/api_sataiga/api/use_cases/prototype_use_case.py", line 77, in get_by_client
    return not_found(f'No se encontraron protoripos para el cliente: {client.name}')
                                                                      ^^^^^^^^^^^
AttributeError: 'dict' object has no attribute 'name'

ERROR 2025-03-31 03:10:26,323 log 22871 6185660416 Internal Server Error: /api/prototype_by_client/67ea0785f84d6a0c075d0c2a
INFO 2025-03-31 03:10:58,930 autoreload 22871 8545306688 /Users/aemo/Projects/api_sataiga/api_sataiga/api/use_cases/prototype_use_case.py changed, reloading.
INFO 2025-03-31 03:10:59,396 autoreload 26019 8545306688 Watching for file changes with StatReloader
WARNING 2025-03-31 03:11:05,499 log 26019 6201716736 Not Found: /api/prototype_by_client/67ea0785f84d6a0c075d0c2a
WARNING 2025-03-31 03:46:36,721 log 26019 6235369472 Method Not Allowed: /api/clients
WARNING 2025-03-31 03:46:56,331 log 26019 6252195840 Method Not Allowed: /api/clients
WARNING 2025-03-31 03:47:30,091 log 26019 6269022208 Method Not Allowed: /api/clients
INFO 2025-03-31 12:59:43,414 autoreload 3047 8463304768 Watching for file changes with StatReloader
