INFO 2025-03-06 19:33:56,612 autoreload 53998 8257288256 Watching for file changes with StatReloader
WARNING 2025-03-06 19:44:11,871 log 53998 6160740352 Bad Request: /api/login
WARNING 2025-03-06 19:44:29,154 log 53998 6177566720 Bad Request: /api/login
INFO 2025-03-06 19:51:33,360 autoreload 53998 8257288256 /Users/aemo/Projects/api_sataiga/api_sataiga/api/use_cases/user_use_case.py changed, reloading.
INFO 2025-03-06 19:51:33,686 autoreload 69705 8257288256 Watching for file changes with StatReloader
INFO 2025-03-06 19:52:47,732 autoreload 69705 8257288256 /Users/aemo/Projects/api_sataiga/api_sataiga/api/use_cases/user_use_case.py changed, reloading.
INFO 2025-03-06 19:52:48,038 autoreload 70815 8257288256 Watching for file changes with StatReloader
INFO 2025-03-06 19:55:35,780 autoreload 70815 8257288256 /Users/aemo/Projects/api_sataiga/api_sataiga/api/use_cases/user_use_case.py changed, reloading.
INFO 2025-03-06 19:55:36,135 autoreload 73268 8257288256 Watching for file changes with StatReloader
INFO 2025-03-06 19:58:22,643 autoreload 73268 8257288256 /Users/aemo/Projects/api_sataiga/api_sataiga/api/use_cases/user_use_case.py changed, reloading.
INFO 2025-03-06 19:58:22,967 autoreload 75737 8257288256 Watching for file changes with StatReloader
ERROR 2025-03-06 19:59:11,715 exception 75737 6206222336 Ocurrió una excepción: cannot access local variable 'params' where it is not associated with a value
ERROR 2025-03-06 19:59:11,718 exception 75737 6206222336 Detalles del traceback:
Traceback (most recent call last):
  File "/Users/aemo/Projects/api_sataiga/venv/lib/python3.13/site-packages/django/core/handlers/base.py", line 197, in _get_response
    response = wrapped_callback(request, *callback_args, **callback_kwargs)
  File "/Users/aemo/Projects/api_sataiga/venv/lib/python3.13/site-packages/django/views/decorators/csrf.py", line 65, in _view_wrapper
    return view_func(request, *args, **kwargs)
  File "/Users/aemo/Projects/api_sataiga/venv/lib/python3.13/site-packages/django/views/generic/base.py", line 104, in view
    return self.dispatch(request, *args, **kwargs)
           ~~~~~~~~~~~~~^^^^^^^^^^^^^^^^^^^^^^^^^^
  File "/Users/aemo/Projects/api_sataiga/venv/lib/python3.13/site-packages/rest_framework/views.py", line 509, in dispatch
    response = self.handle_exception(exc)
  File "/Users/aemo/Projects/api_sataiga/venv/lib/python3.13/site-packages/rest_framework/views.py", line 469, in handle_exception
    self.raise_uncaught_exception(exc)
    ~~~~~~~~~~~~~~~~~~~~~~~~~~~~~^^^^^
  File "/Users/aemo/Projects/api_sataiga/venv/lib/python3.13/site-packages/rest_framework/views.py", line 480, in raise_uncaught_exception
    raise exc
  File "/Users/aemo/Projects/api_sataiga/venv/lib/python3.13/site-packages/rest_framework/views.py", line 506, in dispatch
    response = handler(request, *args, **kwargs)
  File "/Users/aemo/Projects/api_sataiga/api_sataiga/api/views/user.py", line 22, in get
    use_case = UserUseCase(id=id)
  File "/Users/aemo/Projects/api_sataiga/api_sataiga/api/use_cases/user_use_case.py", line 23, in __init__
    self.q = params['q'][0] if 'q' in params else None
                                      ^^^^^^
UnboundLocalError: cannot access local variable 'params' where it is not associated with a value

ERROR 2025-03-06 19:59:11,718 log 75737 6206222336 Internal Server Error: /api/user/67c52e604c0edd407207fbc1
ERROR 2025-03-06 19:59:16,535 exception 75737 6223048704 Ocurrió una excepción: cannot access local variable 'params' where it is not associated with a value
ERROR 2025-03-06 19:59:16,537 exception 75737 6223048704 Detalles del traceback:
Traceback (most recent call last):
  File "/Users/aemo/Projects/api_sataiga/venv/lib/python3.13/site-packages/django/core/handlers/base.py", line 197, in _get_response
    response = wrapped_callback(request, *callback_args, **callback_kwargs)
  File "/Users/aemo/Projects/api_sataiga/venv/lib/python3.13/site-packages/django/views/decorators/csrf.py", line 65, in _view_wrapper
    return view_func(request, *args, **kwargs)
  File "/Users/aemo/Projects/api_sataiga/venv/lib/python3.13/site-packages/django/views/generic/base.py", line 104, in view
    return self.dispatch(request, *args, **kwargs)
           ~~~~~~~~~~~~~^^^^^^^^^^^^^^^^^^^^^^^^^^
  File "/Users/aemo/Projects/api_sataiga/venv/lib/python3.13/site-packages/rest_framework/views.py", line 509, in dispatch
    response = self.handle_exception(exc)
  File "/Users/aemo/Projects/api_sataiga/venv/lib/python3.13/site-packages/rest_framework/views.py", line 469, in handle_exception
    self.raise_uncaught_exception(exc)
    ~~~~~~~~~~~~~~~~~~~~~~~~~~~~~^^^^^
  File "/Users/aemo/Projects/api_sataiga/venv/lib/python3.13/site-packages/rest_framework/views.py", line 480, in raise_uncaught_exception
    raise exc
  File "/Users/aemo/Projects/api_sataiga/venv/lib/python3.13/site-packages/rest_framework/views.py", line 506, in dispatch
    response = handler(request, *args, **kwargs)
  File "/Users/aemo/Projects/api_sataiga/api_sataiga/api/views/user.py", line 22, in get
    use_case = UserUseCase(id=id)
  File "/Users/aemo/Projects/api_sataiga/api_sataiga/api/use_cases/user_use_case.py", line 23, in __init__
    self.q = params['q'][0] if 'q' in params else None
                                      ^^^^^^
UnboundLocalError: cannot access local variable 'params' where it is not associated with a value

ERROR 2025-03-06 19:59:16,538 log 75737 6223048704 Internal Server Error: /api/user/67c52e604c0edd407207fbc1
ERROR 2025-03-06 19:59:19,139 exception 75737 6223048704 Ocurrió una excepción: cannot access local variable 'params' where it is not associated with a value
ERROR 2025-03-06 19:59:19,141 exception 75737 6223048704 Detalles del traceback:
Traceback (most recent call last):
  File "/Users/aemo/Projects/api_sataiga/venv/lib/python3.13/site-packages/django/core/handlers/base.py", line 197, in _get_response
    response = wrapped_callback(request, *callback_args, **callback_kwargs)
  File "/Users/aemo/Projects/api_sataiga/venv/lib/python3.13/site-packages/django/views/decorators/csrf.py", line 65, in _view_wrapper
    return view_func(request, *args, **kwargs)
  File "/Users/aemo/Projects/api_sataiga/venv/lib/python3.13/site-packages/django/views/generic/base.py", line 104, in view
    return self.dispatch(request, *args, **kwargs)
           ~~~~~~~~~~~~~^^^^^^^^^^^^^^^^^^^^^^^^^^
  File "/Users/aemo/Projects/api_sataiga/venv/lib/python3.13/site-packages/rest_framework/views.py", line 509, in dispatch
    response = self.handle_exception(exc)
  File "/Users/aemo/Projects/api_sataiga/venv/lib/python3.13/site-packages/rest_framework/views.py", line 469, in handle_exception
    self.raise_uncaught_exception(exc)
    ~~~~~~~~~~~~~~~~~~~~~~~~~~~~~^^^^^
  File "/Users/aemo/Projects/api_sataiga/venv/lib/python3.13/site-packages/rest_framework/views.py", line 480, in raise_uncaught_exception
    raise exc
  File "/Users/aemo/Projects/api_sataiga/venv/lib/python3.13/site-packages/rest_framework/views.py", line 506, in dispatch
    response = handler(request, *args, **kwargs)
  File "/Users/aemo/Projects/api_sataiga/api_sataiga/api/views/user.py", line 22, in get
    use_case = UserUseCase(id=id)
  File "/Users/aemo/Projects/api_sataiga/api_sataiga/api/use_cases/user_use_case.py", line 23, in __init__
    self.q = params['q'][0] if 'q' in params else None
                                      ^^^^^^
UnboundLocalError: cannot access local variable 'params' where it is not associated with a value

ERROR 2025-03-06 19:59:19,141 log 75737 6223048704 Internal Server Error: /api/user/67c52e604c0edd407207fbc1
INFO 2025-03-06 20:22:33,108 autoreload 75737 8257288256 /Users/aemo/Projects/api_sataiga/api_sataiga/api/use_cases/user_use_case.py changed, reloading.
INFO 2025-03-06 20:22:33,497 autoreload 96944 8257288256 Watching for file changes with StatReloader
ERROR 2025-03-06 20:22:39,993 exception 96944 6203207680 Ocurrió una excepción: cannot access local variable 'params' where it is not associated with a value
ERROR 2025-03-06 20:22:39,994 exception 96944 6203207680 Detalles del traceback:
Traceback (most recent call last):
  File "/Users/aemo/Projects/api_sataiga/venv/lib/python3.13/site-packages/django/core/handlers/base.py", line 197, in _get_response
    response = wrapped_callback(request, *callback_args, **callback_kwargs)
  File "/Users/aemo/Projects/api_sataiga/venv/lib/python3.13/site-packages/django/views/decorators/csrf.py", line 65, in _view_wrapper
    return view_func(request, *args, **kwargs)
  File "/Users/aemo/Projects/api_sataiga/venv/lib/python3.13/site-packages/django/views/generic/base.py", line 104, in view
    return self.dispatch(request, *args, **kwargs)
           ~~~~~~~~~~~~~^^^^^^^^^^^^^^^^^^^^^^^^^^
  File "/Users/aemo/Projects/api_sataiga/venv/lib/python3.13/site-packages/rest_framework/views.py", line 509, in dispatch
    response = self.handle_exception(exc)
  File "/Users/aemo/Projects/api_sataiga/venv/lib/python3.13/site-packages/rest_framework/views.py", line 469, in handle_exception
    self.raise_uncaught_exception(exc)
    ~~~~~~~~~~~~~~~~~~~~~~~~~~~~~^^^^^
  File "/Users/aemo/Projects/api_sataiga/venv/lib/python3.13/site-packages/rest_framework/views.py", line 480, in raise_uncaught_exception
    raise exc
  File "/Users/aemo/Projects/api_sataiga/venv/lib/python3.13/site-packages/rest_framework/views.py", line 506, in dispatch
    response = handler(request, *args, **kwargs)
  File "/Users/aemo/Projects/api_sataiga/api_sataiga/api/views/user.py", line 22, in get
    use_case = UserUseCase(id=id)
  File "/Users/aemo/Projects/api_sataiga/api_sataiga/api/use_cases/user_use_case.py", line 24, in __init__
    self.q = params['q'][0] if 'q' in params else None
                                      ^^^^^^
UnboundLocalError: cannot access local variable 'params' where it is not associated with a value

ERROR 2025-03-06 20:22:39,995 log 96944 6203207680 Internal Server Error: /api/user/67c52e604c0edd407207fbc1
INFO 2025-03-06 20:23:12,725 autoreload 96944 8257288256 /Users/aemo/Projects/api_sataiga/api_sataiga/api/use_cases/user_use_case.py changed, reloading.
INFO 2025-03-06 20:23:13,065 autoreload 97507 8257288256 Watching for file changes with StatReloader
WARNING 2025-03-06 20:23:17,622 log 97507 6157709312 Not Found: /apps/invoice
INFO 2025-03-06 20:23:26,595 autoreload 97507 8257288256 /Users/aemo/Projects/api_sataiga/api_sataiga/api/use_cases/user_use_case.py changed, reloading.
INFO 2025-03-06 20:23:26,885 autoreload 97732 8257288256 Watching for file changes with StatReloader
WARNING 2025-03-06 20:30:43,616 log 97732 6197325824 Not Found: /apps/invoice
WARNING 2025-03-06 20:33:36,291 log 97732 6197325824 Not Found: /apps/invoice
WARNING 2025-03-06 20:34:22,845 log 97732 6197325824 Not Found: /apps/invoice
WARNING 2025-03-06 20:54:37,943 log 97732 6247804928 Not Found: /apps/invoice
WARNING 2025-03-06 21:09:45,994 log 97732 6281457664 Not Found: /apps/invoice
WARNING 2025-03-06 22:16:39,320 log 97732 6214152192 Not Found: /apps/invoice
WARNING 2025-03-06 22:17:44,404 log 97732 6230978560 Not Found: /apps/invoice
WARNING 2025-03-06 22:40:59,247 log 97732 6247804928 Not Found: /apps/invoice
